<?xml version="1.0" ?>
<!-- =================================================================================== -->
<!-- |    This document was autogenerated by xacro from LD60_castors.xacro             | -->
<!-- |    EDITING THIS FILE BY HAND IS NOT RECOMMENDED                                 | -->
<!-- =================================================================================== -->
<robot name="ld60_castors">
  <material name="blue">
    <color rgba="0 0 0.8 1"/>
  </material>
  <material name="black">
    <color rgba="0 0 0 1"/>
  </material>
  <material name="white">
    <color rgba="1 1 1 1"/>
  </material>
  <link name="base_link">
  </link>
  <joint name="base_to_main_body" type="fixed">
    <parent link="base_link"/>
    <child link="main_body"/>
    <origin xyz="0 0 0.085"/>
  </joint>
  <link name="main_body">
    <visual>
      <origin rpy="1.5707963267949 0 1.5707963267949" xyz="0 0 0"/>
      <geometry>
        <mesh filename="meshes/LD_Platform.STL"/>
      </geometry>
      <material name="white"/>
    </visual>
    <inertial>
      <mass value="4.07"/>
      <inertia ixx="0.426" ixy="0.0" ixz="0.0" iyy="0.496" iyz="0.0" izz="0.91"/>
    </inertial>
  </link>
  <link name="left_wheel">
    <visual>
      <origin rpy="0 0 0" xyz="0 0 0"/>
      <geometry>
        <cylinder length="0.03937" radius="0.088"/>
      </geometry>
      <material name="black"/>
    </visual>
    <collision>
      <geometry>
        <cylinder length="0.00039370000000000003" radius="0.088"/>
      </geometry>
    </collision>
    <inertial>
      <mass value="0.17"/>
      <inertia ixx="0.000204" ixy="0.0" ixz="0.0" iyy="0.000204" iyz="0.0" izz="0.000306"/>
    </inertial>
  </link>
  <joint name="left_wheel_joint" type="continuous">
    <axis rpy="0 0 0" xyz="0 0 1"/>
    <parent link="main_body"/>
    <child link="left_wheel"/>
    <origin rpy="-1.57 0 0" xyz="0 0.196425 0.0018809999999999999"/>
  </joint>
  <link name="right_wheel">
    <visual>
      <origin rpy="0 0 0" xyz="0 0 0"/>
      <geometry>
        <cylinder length="0.03937" radius="0.088"/>
      </geometry>
      <material name="black"/>
    </visual>
    <collision>
      <geometry>
        <cylinder length="0.00039370000000000003" radius="0.088"/>
      </geometry>
    </collision>
    <inertial>
      <mass value="0.17"/>
      <inertia ixx="0.000204" ixy="0.0" ixz="0.0" iyy="0.000204" iyz="0.0" izz="0.000306"/>
    </inertial>
  </link>
  <joint name="right_wheel_joint" type="continuous">
    <axis rpy="0 0 0" xyz="0 0 1"/>
    <parent link="main_body"/>
    <child link="right_wheel"/>
    <origin rpy="-1.57 0 0" xyz="0 -0.196425 0.0018809999999999999"/>
  </joint>
  <link name="lf_castor_base">
    <inertial>
      <mass value="0.01"/>
      <inertia ixx="0.0000001" ixy="0.0" ixz="0.0" iyy="0.0000001" iyz="0.0" izz="0.0000001"/>
    </inertial>
  </link>
  <joint name="main_body_to_lf_castor_base" type="continuous">
    <parent link="main_body"/>
    <child link="lf_castor_base"/>
    <origin xyz="0.23399999999999999 0.108 -0.049"/>
    <axis xyz="0 0 1"/>
  </joint>
  <link name="rf_castor_base">
    <inertial>
      <mass value="0.01"/>
      <inertia ixx="0.0000001" ixy="0.0" ixz="0.0" iyy="0.0000001" iyz="0.0" izz="0.0000001"/>
    </inertial>
  </link>
  <joint name="main_body_to_rf_castor_base" type="continuous">
    <parent link="main_body"/>
    <child link="rf_castor_base"/>
    <origin xyz="0.23399999999999999 -0.108 -0.049"/>
    <axis xyz="0 0 1"/>
  </joint>
  <link name="lb_castor_base">
    <inertial>
      <mass value="0.01"/>
      <inertia ixx="0.0000001" ixy="0.0" ixz="0.0" iyy="0.0000001" iyz="0.0" izz="0.0000001"/>
    </inertial>
  </link>
  <joint name="main_body_to_lb_castor_base" type="continuous">
    <parent link="main_body"/>
    <child link="lb_castor_base"/>
    <origin xyz="-0.203 0.156 -0.049"/>
    <axis xyz="0 0 1"/>
  </joint>
  <link name="rb_castor_base">
    <inertial>
      <mass value="0.01"/>
      <inertia ixx="0.0000001" ixy="0.0" ixz="0.0" iyy="0.0000001" iyz="0.0" izz="0.0000001"/>
    </inertial>
  </link>
  <joint name="main_body_to_rb_castor_base" type="continuous">
    <parent link="main_body"/>
    <child link="rb_castor_base"/>
    <origin xyz="-0.203 -0.156 -0.049"/>
    <axis xyz="0 0 1"/>
  </joint>
  <link name="lf_castor_wheel">
    <visual>
      <geometry>
        <cylinder length="0.02775" radius="0.0375"/>
      </geometry>
      <material name="black"/>
    </visual>
    <collision>
      <geometry>
        <cylinder length="0.0002775" radius="0.0375"/>
      </geometry>
    </collision>
    <inertial>
      <mass value="0.17"/>
      <inertia ixx="0.000204" ixy="0.0" ixz="0.0" iyy="0.000204" iyz="0.0" izz="0.000306"/>
    </inertial>
  </link>
  <joint name="lf_castor_base_to_lf_castor_wheel" type="continuous">
    <parent link="lf_castor_base"/>
    <child link="lf_castor_wheel"/>
    <origin rpy="-1.57 0 0" xyz="-0.025 0 0"/>
    <axis xyz="0 0 1"/>
  </joint>
  <link name="rf_castor_wheel">
    <visual>
      <geometry>
        <cylinder length="0.02775" radius="0.0375"/>
      </geometry>
      <material name="black"/>
    </visual>
    <collision>
      <geometry>
        <cylinder length="0.0002775" radius="0.0375"/>
      </geometry>
    </collision>
    <inertial>
      <mass value="0.17"/>
      <inertia ixx="0.000204" ixy="0.0" ixz="0.0" iyy="0.000204" iyz="0.0" izz="0.000306"/>
    </inertial>
  </link>
  <joint name="rf_castor_base_to_rf_castor_wheel" type="continuous">
    <parent link="rf_castor_base"/>
    <child link="rf_castor_wheel"/>
    <origin rpy="-1.57 0 0" xyz="-0.025 0 0"/>
    <axis xyz="0 0 1"/>
  </joint>
  <link name="lb_castor_wheel">
    <visual>
      <geometry>
        <cylinder length="0.02775" radius="0.0375"/>
      </geometry>
      <material name="black"/>
    </visual>
    <collision>
      <geometry>
        <cylinder length="0.0002775" radius="0.0375"/>
      </geometry>
    </collision>
    <inertial>
      <mass value="0.17"/>
      <inertia ixx="0.000204" ixy="0.0" ixz="0.0" iyy="0.000204" iyz="0.0" izz="0.000306"/>
    </inertial>
  </link>
  <joint name="lb_castor_base_to_lb_castor_wheel" type="continuous">
    <parent link="lb_castor_base"/>
    <child link="lb_castor_wheel"/>
    <origin rpy="-1.57 0 0" xyz="-0.025 0 0"/>
    <axis xyz="0 0 1"/>
  </joint>
  <link name="rb_castor_wheel">
    <visual>
      <geometry>
        <cylinder length="0.02775" radius="0.0375"/>
      </geometry>
      <material name="black"/>
    </visual>
    <collision>
      <geometry>
        <cylinder length="0.0002775" radius="0.0375"/>
      </geometry>
    </collision>
    <inertial>
      <mass value="0.17"/>
      <inertia ixx="0.000204" ixy="0.0" ixz="0.0" iyy="0.000204" iyz="0.0" izz="0.000306"/>
    </inertial>
  </link>
  <joint name="rb_castor_base_to_rb_castor_wheel" type="continuous">
    <parent link="rb_castor_base"/>
    <child link="rb_castor_wheel"/>
    <origin rpy="-1.57 0 0" xyz="-0.025 0 0"/>
    <axis xyz="0 0 1"/>
  </joint>
  <!-- Lidar Frames -->
  <link name="lower_laser">
    <inertial>
      <mass value="0.001"/>
      <inertia ixx="0.0000001" ixy="0.0" ixz="0.0" iyy="0.0000001" iyz="0.0" izz="0.0000001"/>
    </inertial>
  </link>
  <link name="upper_laser">
    <inertial>
      <mass value="0.001"/>
      <inertia ixx="0.0000001" ixy="0.0" ixz="0.0" iyy="0.0000001" iyz="0.0" izz="0.0000001"/>
    </inertial>
  </link>
  <joint name="main_body_to_upper_laser" type="fixed">
    <parent link="main_body"/>
    <child link="upper_laser"/>
    <origin xyz="0.27 0 0.11"/>
  </joint>
  <joint name="main_body_to_lower_laser" type="fixed">
    <parent link="main_body"/>
    <child link="lower_laser"/>
    <origin xyz="0.27 0 -0.03"/>
  </joint>
  <gazebo reference="right_wheel">
    <material>Gazebo/Black</material>
  </gazebo>
  <gazebo reference="left_wheel">
    <material>Gazebo/Black</material>
  </gazebo>
  <gazebo reference="main_body">
    <material>Gazebo/White</material>
  </gazebo>
  <gazebo reference="lf_castor_wheel">
    <material>Gazebo/Black</material>
  </gazebo>
  <gazebo reference="rf_castor_wheel">
    <material>Gazebo/Black</material>
  </gazebo>
  <gazebo reference="lb_castor_wheel">
    <material>Gazebo/Black</material>
  </gazebo>
  <gazebo reference="rb_castor_wheel">
    <material>Gazebo/Black</material>
  </gazebo>
  <gazebo>
    <plugin filename="libgazebo_ros_diff_drive.so" name="differential_drive_controller">
      <updateRate>20</updateRate>
      <!-- Plugin update rate in Hz -->
      <leftJoint>left_wheel_joint</leftJoint>
      <!-- Name of left joint, defaults to `left_joint` -->
      <rightJoint>right_wheel_joint</rightJoint>
      <!-- Name of right joint, defaults to `right_joint` -->
      <wheelSeparation>0.39285</wheelSeparation>
      <!-- The distance from the center of one wheel to the other, in meters, defaults to 0.34 m -->
      <wheelDiameter>0.176</wheelDiameter>
      <!-- Diameter of the wheels, in meters, defaults to 0.15 m -->
      <wheelAcceleration>1.0</wheelAcceleration>
      <!-- Wheel acceleration, in rad/s^2, defaults to 0.0 rad/s^2 -->
      <wheelTorque>20</wheelTorque>
      <!-- Maximum torque which the wheels can produce, in Nm, defaults to 5 Nm -->
      <commandTopic>cmd_vel</commandTopic>
      <!-- Topic to receive geometry_msgs/Twist message commands, defaults to `cmd_vel` -->
      <odometryTopic>odom</odometryTopic>
      <!-- Topic to publish nav_msgs/Odometry messages, defaults to `odom` -->
      <odometryFrame>odom_frame</odometryFrame>
      <!-- Odometry frame, defaults to `odom` -->
      <robotBaseFrame>base_link</robotBaseFrame>
      <!-- Robot frame to calculate odometry from, defaults to `base_footprint` -->
      <odometrySource>1</odometrySource>
      <!-- Odometry source, 0 for ENCODER, 1 for WORLD, defaults to WORLD -->
      <publishWheelTF>false</publishWheelTF>
      <!-- Set to true to publish transforms for the wheel links, defaults to false -->
      <publishOdom>true</publishOdom>
      <!-- Set to true to publish transforms for the odometry, defaults to true -->
      <publishWheelJointState>true</publishWheelJointState>
      <!-- Set to true to publish sensor_msgs/JointState on /joint_states for the wheel joints, defaults to false -->
      <legacyMode>false</legacyMode>
      <!-- Set to true to swap right and left wheels, defaults to true -->
    </plugin>
  </gazebo>
</robot>

